2025-07-15T16:01:58|CRITICAL|root|Unhandled exception: Traceback (most recent call last):
  File "c:\Users\Auden\Dropbox\PC (2)\Documents\Jupyter\phys 111b\Segre-Internship\GMAMicroscope\fancy_app.py", line 24, in <module>
    app = FancyApp(sys.argv)
          ^^^^^^^^^^^^^^^^^^
  File "C:\Users\Auden\AppData\Local\Programs\Python\Python312\Lib\site-packages\ScopeFoundry\base_app\base_microscope_app.py", line 93, in __init__
    self._setup_ui_mdi_area()
  File "C:\Users\Auden\AppData\Local\Programs\Python\Python312\Lib\site-packages\ScopeFoundry\base_app\base_microscope_app.py", line 250, in _setup_ui_mdi_area
    ui = self.load_measure_ui(measure)
         ^^^^^^^^^^^^^^^^^^^^^^^^^^^^^
  File "C:\Users\Auden\AppData\Local\Programs\Python\Python312\Lib\site-packages\ScopeFoundry\base_app\base_microscope_app.py", line 384, in load_measure_ui
    measure.setup_figure()
  File "c:\Users\Auden\Dropbox\PC (2)\Documents\Jupyter\phys 111b\Segre-Internship\GMAMicroscope\measurements\scope_read.py", line 47, in setup_figure
    x = self.data["x"]
        ~~~~~~~~~^^^^^
KeyError: 'x'

