2025-07-07T15:02:32|INFO|FancyApp|proposed values default_settings.ini
2025-07-07T15:02:32|INFO|FancyApp|settings loaded from default_settings.ini
2025-07-07T15:02:32|INFO|FancyApp|proposed values default_settings.ini
2025-07-07T15:02:32|INFO|FancyApp|settings loaded from default_settings.ini
2025-07-07T15:02:43|CRITICAL|root|Unhandled exception: Traceback (most recent call last):
  File "c:\Users\Auden\Dropbox\PC (2)\Documents\Jupyter\phys 111b\Segre-Internship\GMAMicroscope\ScopeFoundryHW\NIDAQ.py", line 143, in set_channel
    self.task.CreateAOVoltageChan(self._channel, '', -10.0, +10.0, mx.DAQmx_Val_Volts, '')
  File "<string>", line 3, in CreateAOVoltageChan
  File "<string>", line 2, in function
  File "C:\Users\Auden\AppData\Local\Programs\Python\Python312\Lib\site-packages\PyDAQmx\DAQmxFunctions.py", line 62, in mafunction
    raise exception_class(errBuff.value.decode("utf-8"), f.__name__)
PyDAQmx.DAQmxFunctions.InvalidPhysChanNameError: Physical channel name specified is invalid. Physical channel names are of the form <device name>/<physical channel name>, for example, dev1/ai0.

Task Name: ni_dac
Status Code: -201237
 in function DAQmxCreateAOVoltageChan

During handling of the above exception, another exception occurred:

Traceback (most recent call last):
  File "C:\Users\Auden\AppData\Local\Programs\Python\Python312\Lib\site-packages\ScopeFoundry\hardware.py", line 107, in enable_connection
    raise err
  File "C:\Users\Auden\AppData\Local\Programs\Python\Python312\Lib\site-packages\ScopeFoundry\hardware.py", line 97, in enable_connection
    self.connect()
  File "c:\Users\Auden\Dropbox\PC (2)\Documents\Jupyter\phys 111b\Segre-Internship\GMAMicroscope\ScopeFoundryHW\NIDAQ.py", line 309, in connect
    self.dac_task = NI_DacTask(channel=S['channel'],
                    ^^^^^^^^^^^^^^^^^^^^^^^^^^^^^^^^
  File "c:\Users\Auden\Dropbox\PC (2)\Documents\Jupyter\phys 111b\Segre-Internship\GMAMicroscope\ScopeFoundryHW\NIDAQ.py", line 134, in __init__
    self.set_channel(channel)
  File "c:\Users\Auden\Dropbox\PC (2)\Documents\Jupyter\phys 111b\Segre-Internship\GMAMicroscope\ScopeFoundryHW\NIDAQ.py", line 151, in set_channel
    self.error(err)
  File "c:\Users\Auden\Dropbox\PC (2)\Documents\Jupyter\phys 111b\Segre-Internship\GMAMicroscope\ScopeFoundryHW\NIDAQ.py", line 47, in error
    logger.error('Error calling "{}": {}'.format( err.fname, err.mess ))
                                                             ^^^^^^^^
AttributeError: 'InvalidPhysChanNameError' object has no attribute 'mess'

2025-07-07T15:04:34|CRITICAL|root|Unhandled exception: Traceback (most recent call last):
  File "C:\Users\Auden\AppData\Local\Programs\Python\Python312\Lib\site-packages\ScopeFoundry\helper_funcs.py", line 188, in eventFilter
    def eventFilter(self, obj, event):
    
KeyboardInterrupt

2025-07-07T15:04:37|INFO|FancyApp|on_close
2025-07-07T15:04:37|INFO|FancyApp|disconnecting ni_dac
