2025-07-15T16:06:35|INFO|FancyApp|proposed values default_settings.ini
2025-07-15T16:06:35|INFO|FancyApp|settings loaded from default_settings.ini
2025-07-15T16:06:42|ERROR|ScopeRead|read_scope failed to update display: 'y'. Traceback (most recent call last):

  File "C:\Users\Auden\AppData\Local\Programs\Python\Python312\Lib\site-packages\ScopeFoundry\measurement.py", line 672, in _on_display_update_timer
    self.m.update_display()

  File "c:\Users\Auden\Dropbox\PC (2)\Documents\Jupyter\phys 111b\Segre-Internship\GMAMicroscope\measurements\scope_read.py", line 79, in update_display
    self.plot_lines["y"].setData(self.data["y"])
                                 ~~~~~~~~~^^^^^

KeyError: 'y'

2025-07-15T16:06:42|ERROR|ScopeRead|read_scope failed to update display: 'y'. Traceback (most recent call last):

  File "C:\Users\Auden\AppData\Local\Programs\Python\Python312\Lib\site-packages\ScopeFoundry\measurement.py", line 672, in _on_display_update_timer
    self.m.update_display()

  File "c:\Users\Auden\Dropbox\PC (2)\Documents\Jupyter\phys 111b\Segre-Internship\GMAMicroscope\measurements\scope_read.py", line 79, in update_display
    self.plot_lines["y"].setData(self.data["y"])
                                 ~~~~~~~~~^^^^^

KeyError: 'y'

2025-07-15T16:06:42|ERROR|ScopeRead|read_scope failed to update display: 'y'. Traceback (most recent call last):

  File "C:\Users\Auden\AppData\Local\Programs\Python\Python312\Lib\site-packages\ScopeFoundry\measurement.py", line 672, in _on_display_update_timer
    self.m.update_display()

  File "c:\Users\Auden\Dropbox\PC (2)\Documents\Jupyter\phys 111b\Segre-Internship\GMAMicroscope\measurements\scope_read.py", line 79, in update_display
    self.plot_lines["y"].setData(self.data["y"])
                                 ~~~~~~~~~^^^^^

KeyError: 'y'

2025-07-15T16:06:42|ERROR|ScopeRead|read_scope failed to update display: 'y'. Traceback (most recent call last):

  File "C:\Users\Auden\AppData\Local\Programs\Python\Python312\Lib\site-packages\ScopeFoundry\measurement.py", line 672, in _on_display_update_timer
    self.m.update_display()

  File "c:\Users\Auden\Dropbox\PC (2)\Documents\Jupyter\phys 111b\Segre-Internship\GMAMicroscope\measurements\scope_read.py", line 79, in update_display
    self.plot_lines["y"].setData(self.data["y"])
                                 ~~~~~~~~~^^^^^

KeyError: 'y'

2025-07-15T16:06:42|CRITICAL|root|Unhandled exception: Traceback (most recent call last):
  File "C:\Users\Auden\AppData\Local\Programs\Python\Python312\Lib\site-packages\ScopeFoundry\measurement.py", line 38, in run
    self.measurement._thread_run()
  File "C:\Users\Auden\AppData\Local\Programs\Python\Python312\Lib\site-packages\ScopeFoundry\measurement.py", line 251, in _thread_run
    self.run()
  File "c:\Users\Auden\Dropbox\PC (2)\Documents\Jupyter\phys 111b\Segre-Internship\GMAMicroscope\measurements\scope_read.py", line 31, in run
    hw.open_scope()
  File "c:\Users\Auden\Dropbox\PC (2)\Documents\Jupyter\phys 111b\Segre-Internship\GMAMicroscope\ScopeFoundryHW\ADS.py", line 27, in open_scope
    scope.open(self.handle, buffer_size=buffer_size, sampling_frequency=sample_freq)
  File "C:\Users\Auden\AppData\Local\Programs\Python\Python312\Lib\site-packages\WF_SDK\scope.py", line 63, in open
    check_error()
  File "C:\Users\Auden\AppData\Local\Programs\Python\Python312\Lib\site-packages\WF_SDK\device.py", line 229, in check_error
    raise error(err_msg, err_func, err_inst)
WF_SDK.device.error: Error: scope -> open -> Invalid device handle provided


2025-07-15T16:06:42|ERROR|ScopeRead|read_scope failed to update display: 'y'. Traceback (most recent call last):

  File "C:\Users\Auden\AppData\Local\Programs\Python\Python312\Lib\site-packages\ScopeFoundry\measurement.py", line 672, in _on_display_update_timer
    self.m.update_display()

  File "c:\Users\Auden\Dropbox\PC (2)\Documents\Jupyter\phys 111b\Segre-Internship\GMAMicroscope\measurements\scope_read.py", line 79, in update_display
    self.plot_lines["y"].setData(self.data["y"])
                                 ~~~~~~~~~^^^^^

KeyError: 'y'

2025-07-15T16:07:52|INFO|FancyApp|on_close
2025-07-15T16:07:52|INFO|FancyApp|disconnecting ni_dac
2025-07-15T16:07:52|INFO|FancyApp|disconnecting ads
