2025-07-07T16:23:56|INFO|FancyApp|proposed values default_settings.ini
2025-07-07T16:23:56|INFO|FancyApp|settings loaded from default_settings.ini
2025-07-07T16:24:08|ERROR|ScopeFoundryHW.NIDAQ|Error calling "DAQmxCreateAOVoltageChan": Device identifier is invalid.

Device Specified: Dev1

Task Name: ni_dac
Status Code: -200220
2025-07-07T16:24:08|ERROR|ScopeFoundryHW.NIDAQ|Error calling "DAQmxCreateAOVoltageChan": Device identifier is invalid.

Device Specified: Dev1

Task Name: ni_dac
Status Code: -200220
2025-07-07T16:24:08|ERROR|ScopeFoundryHW.NIDAQ|Error calling "DAQmxStartTask": Specified operation cannot be performed when there are no channels in the task.

Task Name: ni_dac
Status Code: -200478
2025-07-07T16:28:24|CRITICAL|root|Unhandled exception: Traceback (most recent call last):
  File "C:\Users\Auden\AppData\Local\Programs\Python\Python312\Lib\site-packages\ScopeFoundry\measurement.py", line 38, in run
    self.measurement._thread_run()
  File "C:\Users\Auden\AppData\Local\Programs\Python\Python312\Lib\site-packages\ScopeFoundry\measurement.py", line 251, in _thread_run
    self.run()
  File "c:\Users\Auden\Dropbox\PC (2)\Documents\Jupyter\phys 111b\Segre-Internship\GMAMicroscope\measurements\pulse_height.py", line 37, in run
    hw = self.app.hardware["ni_dac"]
         ^^^^^^^^^^^^^^^^^^^^^^^^^^
  File "C:\Users\Auden\AppData\Local\Programs\Python\Python312\Lib\site-packages\ScopeFoundry\helper_funcs.py", line 41, in __getitem__
    return self._odict[key]
           ~~~~~~~~~~~^^^^^
KeyError: 'nidaq'

2025-07-07T16:28:28|CRITICAL|root|Unhandled exception: Traceback (most recent call last):
  File "C:\Users\Auden\AppData\Local\Programs\Python\Python312\Lib\site-packages\ScopeFoundry\measurement.py", line 38, in run
    self.measurement._thread_run()
  File "C:\Users\Auden\AppData\Local\Programs\Python\Python312\Lib\site-packages\ScopeFoundry\measurement.py", line 251, in _thread_run
    self.run()
  File "c:\Users\Auden\Dropbox\PC (2)\Documents\Jupyter\phys 111b\Segre-Internship\GMAMicroscope\measurements\pulse_height.py", line 37, in run
    hw = self.app.hardware["ni_dac"]
         ^^^^^^^^^^^^^^^^^^^^^^^^^^
  File "C:\Users\Auden\AppData\Local\Programs\Python\Python312\Lib\site-packages\ScopeFoundry\helper_funcs.py", line 41, in __getitem__
    return self._odict[key]
           ~~~~~~~~~~~^^^^^
KeyError: 'nidaq'

2025-07-07T16:28:34|CRITICAL|root|Unhandled exception: Traceback (most recent call last):
  File "C:\Users\Auden\AppData\Local\Programs\Python\Python312\Lib\site-packages\ScopeFoundry\measurement.py", line 38, in run
    self.measurement._thread_run()
  File "C:\Users\Auden\AppData\Local\Programs\Python\Python312\Lib\site-packages\ScopeFoundry\measurement.py", line 251, in _thread_run
    self.run()
  File "c:\Users\Auden\Dropbox\PC (2)\Documents\Jupyter\phys 111b\Segre-Internship\GMAMicroscope\measurements\pulse_height.py", line 37, in run
    hw = self.app.hardware["ni_dac"]
         ^^^^^^^^^^^^^^^^^^^^^^^^^^
  File "C:\Users\Auden\AppData\Local\Programs\Python\Python312\Lib\site-packages\ScopeFoundry\helper_funcs.py", line 41, in __getitem__
    return self._odict[key]
           ~~~~~~~~~~~^^^^^
KeyError: 'nidaq'

2025-07-07T16:28:43|INFO|FancyApp|on_close
2025-07-07T16:28:43|INFO|FancyApp|disconnecting ni_dac
