2025-07-07T14:59:32|INFO|FancyApp|proposed values default_settings.ini
2025-07-07T14:59:32|INFO|FancyApp|settings loaded from default_settings.ini
2025-07-07T14:59:38|CRITICAL|root|Unhandled exception: Traceback (most recent call last):
  File "c:\Users\Auden\Dropbox\PC (2)\Documents\Jupyter\phys 111b\Segre-Internship\GMAMicroscope\ScopeFoundryHW\NIDAQ.py", line 143, in set_channel
    self.task.CreateAOVoltageChan(self._channel, '', -10.0, +10.0, mx.DAQmx_Val_Volts, '')
  File "<string>", line 3, in CreateAOVoltageChan
  File "<string>", line 2, in function
  File "C:\Users\Auden\AppData\Local\Programs\Python\Python312\Lib\site-packages\PyDAQmx\DAQmxFunctions.py", line 62, in mafunction
    raise exception_class(errBuff.value.decode("utf-8"), f.__name__)
PyDAQmx.DAQmxFunctions.InvalidDeviceIDError: Device identifier is invalid.

Device Specified: Dev1

Task Name: ni_dac
Status Code: -200220
 in function DAQmxCreateAOVoltageChan

During handling of the above exception, another exception occurred:

Traceback (most recent call last):
  File "C:\Users\Auden\AppData\Local\Programs\Python\Python312\Lib\site-packages\ScopeFoundry\hardware.py", line 107, in enable_connection
    raise err
  File "C:\Users\Auden\AppData\Local\Programs\Python\Python312\Lib\site-packages\ScopeFoundry\hardware.py", line 97, in enable_connection
    self.connect()
  File "c:\Users\Auden\Dropbox\PC (2)\Documents\Jupyter\phys 111b\Segre-Internship\GMAMicroscope\ScopeFoundryHW\NIDAQ.py", line 309, in connect
    self.dac_task = NI_DacTask(channel=S['channel'],
                    ^^^^^^^^^^^^^^^^^^^^^^^^^^^^^^^^
  File "c:\Users\Auden\Dropbox\PC (2)\Documents\Jupyter\phys 111b\Segre-Internship\GMAMicroscope\ScopeFoundryHW\NIDAQ.py", line 134, in __init__
    self.set_channel(channel)
  File "c:\Users\Auden\Dropbox\PC (2)\Documents\Jupyter\phys 111b\Segre-Internship\GMAMicroscope\ScopeFoundryHW\NIDAQ.py", line 151, in set_channel
    self.error(err)
  File "c:\Users\Auden\Dropbox\PC (2)\Documents\Jupyter\phys 111b\Segre-Internship\GMAMicroscope\ScopeFoundryHW\NIDAQ.py", line 47, in error
    logger.error('Error calling "{}": {}'.format( err.fname, err.mess ))
                                                             ^^^^^^^^
AttributeError: 'InvalidDeviceIDError' object has no attribute 'mess'

2025-07-07T14:59:44|CRITICAL|root|Unhandled exception: Traceback (most recent call last):
  File "c:\Users\Auden\Dropbox\PC (2)\Documents\Jupyter\phys 111b\Segre-Internship\GMAMicroscope\ScopeFoundryHW\NIDAQ.py", line 40, in make_task
    self.task = NamedTask(name)
        ^^^^^^^^^^^^^^^
  File "c:\Users\Auden\Dropbox\PC (2)\Documents\Jupyter\phys 111b\Segre-Internship\GMAMicroscope\ScopeFoundryHW\NIDAQ.py", line 17, in __init__
    mx.DAQmxCreateTask(name, mx.byref(self.taskHandle))
  File "<string>", line 2, in function
  File "C:\Users\Auden\AppData\Local\Programs\Python\Python312\Lib\site-packages\PyDAQmx\DAQmxFunctions.py", line 62, in mafunction
    raise exception_class(errBuff.value.decode("utf-8"), f.__name__)
PyDAQmx.DAQmxFunctions.DuplicateTaskError: Task name specified conflicts with an existing task name.

Task Name: ni_dac
Status Code: -200089
 in function DAQmxCreateTask

During handling of the above exception, another exception occurred:

Traceback (most recent call last):
  File "C:\Users\Auden\AppData\Local\Programs\Python\Python312\Lib\site-packages\ScopeFoundry\hardware.py", line 107, in enable_connection
    raise err
  File "C:\Users\Auden\AppData\Local\Programs\Python\Python312\Lib\site-packages\ScopeFoundry\hardware.py", line 97, in enable_connection
    self.connect()
  File "c:\Users\Auden\Dropbox\PC (2)\Documents\Jupyter\phys 111b\Segre-Internship\GMAMicroscope\ScopeFoundryHW\NIDAQ.py", line 309, in connect
    self.dac_task = NI_DacTask(channel=S['channel'],
                    ^^^^^^^^^^^^^^^^^^^^^^^^^^^^^^^^
  File "c:\Users\Auden\Dropbox\PC (2)\Documents\Jupyter\phys 111b\Segre-Internship\GMAMicroscope\ScopeFoundryHW\NIDAQ.py", line 132, in __init__
    NI_TaskWrap.__init__(self, name)
  File "c:\Users\Auden\Dropbox\PC (2)\Documents\Jupyter\phys 111b\Segre-Internship\GMAMicroscope\ScopeFoundryHW\NIDAQ.py", line 30, in __init__
    self.make_task( name )
  File "c:\Users\Auden\Dropbox\PC (2)\Documents\Jupyter\phys 111b\Segre-Internship\GMAMicroscope\ScopeFoundryHW\NIDAQ.py", line 42, in make_task
    self.error( err )
  File "c:\Users\Auden\Dropbox\PC (2)\Documents\Jupyter\phys 111b\Segre-Internship\GMAMicroscope\ScopeFoundryHW\NIDAQ.py", line 47, in error
    logger.error('Error calling "{}": {}'.format( err.fname, err.mess ))
                                                             ^^^^^^^^
AttributeError: 'DuplicateTaskError' object has no attribute 'mess'

2025-07-07T14:59:54|INFO|FancyApp|on_close
2025-07-07T14:59:54|INFO|FancyApp|disconnecting ni_dac
